<?xml version="1.0" ?>
<robot name="panda">
	<link name="panda_link0">
		<visual>
			<origin xyz="0 0 0" rpy="0 0 0"/>
			<geometry>
				<mesh filename="merged_meshes/panda_link0_visual.obj"/>
			</geometry>
		</visual>
		<collision>
			<origin xyz="0 0 0" rpy="0 0 0"/>
			<geometry>
				<mesh filename="merged_meshes/panda_link0_collision.obj"/>
			</geometry>
		</collision>
	</link>
	<joint name="panda_joint1" type="revolute">
		<parent link="panda_link0"/>
		<child link="panda_link1"/>
		<origin rpy="0.0 0.0 0.0" xyz="0.0 0.0 0.333"/>
		<safety_controller k_position="100.0" k_velocity="40.0" soft_lower_limit="-2.8973" soft_upper_limit="2.8973"/>
		<axis xyz="0 0 1"/>
		<limit effort="87" lower="-2.9671" upper="2.9671" velocity="2.1750"/>
	</joint>
	<link name="panda_link1">
		<visual>
			<origin xyz="0 0 0" rpy="0 0 0"/>
			<geometry>
				<mesh filename="merged_meshes/panda_link1_visual.obj"/>
			</geometry>
		</visual>
		<collision>
			<origin xyz="0 0 0" rpy="0 0 0"/>
			<geometry>
				<mesh filename="merged_meshes/panda_link1_collision.obj"/>
			</geometry>
		</collision>
	</link>
	<joint name="panda_joint2" type="revolute">
		<parent link="panda_link1"/>
		<child link="panda_link2"/>
		<origin rpy="-1.57079632679 0.0 0.0" xyz="0.0 0.0 0.0"/>
		<safety_controller k_position="100.0" k_velocity="40.0" soft_lower_limit="-1.7628" soft_upper_limit="1.7628"/>
		<axis xyz="0 0 1"/>
		<limit effort="87" lower="-1.8326" upper="1.8326" velocity="2.1750"/>
	</joint>
	<link name="panda_link2">
		<visual>
			<origin xyz="0 0 0" rpy="0 0 0"/>
			<geometry>
				<mesh filename="merged_meshes/panda_link2_visual.obj"/>
			</geometry>
		</visual>
		<collision>
			<origin xyz="0 0 0" rpy="0 0 0"/>
			<geometry>
				<mesh filename="merged_meshes/panda_link2_collision.obj"/>
			</geometry>
		</collision>
	</link>
	<joint name="panda_joint3" type="revolute">
		<parent link="panda_link2"/>
		<child link="panda_link3"/>
		<origin rpy="1.57079632679 0.0 0.0" xyz="0.0 -0.316 0.0"/>
		<safety_controller k_position="100.0" k_velocity="40.0" soft_lower_limit="-2.8973" soft_upper_limit="2.8973"/>
		<axis xyz="0 0 1"/>
		<limit effort="87" lower="-2.9671" upper="2.9671" velocity="2.1750"/>
	</joint>
	<link name="panda_link3">
		<visual>
			<origin xyz="0 0 0" rpy="0 0 0"/>
			<geometry>
				<mesh filename="merged_meshes/panda_link3_visual.obj"/>
			</geometry>
		</visual>
		<collision>
			<origin xyz="0 0 0" rpy="0 0 0"/>
			<geometry>
				<mesh filename="merged_meshes/panda_link3_collision.obj"/>
			</geometry>
		</collision>
	</link>
	<joint name="panda_joint4" type="revolute">
		<parent link="panda_link3"/>
		<child link="panda_link4"/>
		<origin rpy="1.57079632679 0.0 0.0" xyz="0.0825 0.0 0.0"/>
		<safety_controller k_position="100.0" k_velocity="40.0" soft_lower_limit="-3.0718" soft_upper_limit="-0.0698"/>
		<axis xyz="0 0 1"/>
		<limit effort="87" lower="-3.1416" upper="0.0" velocity="2.1750"/>
	</joint>
	<link name="panda_link4">
		<visual>
			<origin xyz="0 0 0" rpy="0 0 0"/>
			<geometry>
				<mesh filename="merged_meshes/panda_link4_visual.obj"/>
			</geometry>
		</visual>
		<collision>
			<origin xyz="0 0 0" rpy="0 0 0"/>
			<geometry>
				<mesh filename="merged_meshes/panda_link4_collision.obj"/>
			</geometry>
		</collision>
	</link>
	<joint name="panda_joint5" type="revolute">
		<parent link="panda_link4"/>
		<child link="panda_link5"/>
		<origin rpy="-1.57079632679 0.0 0.0" xyz="-0.0825 0.384 0.0"/>
		<safety_controller k_position="100.0" k_velocity="40.0" soft_lower_limit="-2.8973" soft_upper_limit="2.8973"/>
		<axis xyz="0 0 1"/>
		<limit effort="12" lower="-2.9671" upper="2.9671" velocity="2.6100"/>
	</joint>
	<link name="panda_link5">
		<visual>
			<origin xyz="0 0 0" rpy="0 0 0"/>
			<geometry>
				<mesh filename="merged_meshes/panda_link5_visual.obj"/>
			</geometry>
		</visual>
		<collision>
			<origin xyz="0 0 0" rpy="0 0 0"/>
			<geometry>
				<mesh filename="merged_meshes/panda_link5_collision.obj"/>
			</geometry>
		</collision>
	</link>
	<joint name="panda_joint6" type="revolute">
		<parent link="panda_link5"/>
		<child link="panda_link6"/>
		<origin rpy="1.57079632679 0.0 0.0" xyz="0.0 0.0 0.0"/>
		<safety_controller k_position="100.0" k_velocity="40.0" soft_lower_limit="-0.0175" soft_upper_limit="3.7525"/>
		<axis xyz="0 0 1"/>
		<limit effort="12" lower="-0.0873" upper="3.8223" velocity="2.6100"/>
	</joint>
	<link name="panda_link6">
		<visual>
			<origin xyz="0 0 0" rpy="0 0 0"/>
			<geometry>
				<mesh filename="merged_meshes/panda_link6_visual.obj"/>
			</geometry>
		</visual>
		<collision>
			<origin xyz="0 0 0" rpy="0 0 0"/>
			<geometry>
				<mesh filename="merged_meshes/panda_link6_collision.obj"/>
			</geometry>
		</collision>
	</link>
	<joint name="panda_joint7" type="revolute">
		<parent link="panda_link6"/>
		<child link="panda_link7"/>
		<origin rpy="1.57079632679 0.0 0.0" xyz="0.088 0.0 0.0"/>
		<safety_controller k_position="100.0" k_velocity="40.0" soft_lower_limit="-2.8973" soft_upper_limit="2.8973"/>
		<axis xyz="0 0 1"/>
		<limit effort="12" lower="-2.9671" upper="2.9671" velocity="2.6100"/>
	</joint>
	<link name="panda_link7">
		<visual>
			<origin xyz="0 0 0" rpy="0 0 0"/>
			<geometry>
				<mesh filename="merged_meshes/panda_link7_visual.obj"/>
			</geometry>
		</visual>
		<collision>
			<origin xyz="0 0 0" rpy="0 0 0"/>
			<geometry>
				<mesh filename="merged_meshes/panda_link7_collision.obj"/>
			</geometry>
		</collision>
	</link>
</robot>
